[2023-08-30T13:29:16.281+0100] {taskinstance.py:1159} INFO - Dependencies all met for dep_context=non-requeueable deps ti=<TaskInstance: schedule_news_extraction.data_process_service_container manual__2023-08-30T12:02:15.528622+00:00 [queued]>
[2023-08-30T13:29:16.288+0100] {taskinstance.py:1159} INFO - Dependencies all met for dep_context=requeueable deps ti=<TaskInstance: schedule_news_extraction.data_process_service_container manual__2023-08-30T12:02:15.528622+00:00 [queued]>
[2023-08-30T13:29:16.289+0100] {taskinstance.py:1361} INFO - Starting attempt 5 of 6
[2023-08-30T13:29:16.302+0100] {taskinstance.py:1382} INFO - Executing <Task(DockerOperator): data_process_service_container> on 2023-08-30 12:02:15.528622+00:00
[2023-08-30T13:29:16.305+0100] {standard_task_runner.py:57} INFO - Started process 98391 to run task
[2023-08-30T13:29:16.308+0100] {standard_task_runner.py:84} INFO - Running: ['airflow', 'tasks', 'run', 'schedule_news_extraction', 'data_process_service_container', 'manual__2023-08-30T12:02:15.528622+00:00', '--job-id', '59', '--raw', '--subdir', '/home/haboubi/Desktop/final/airflow_folder/dags/news_schedule.py', '--cfg-path', '/tmp/tmpi_7zamhi']
[2023-08-30T13:29:16.309+0100] {standard_task_runner.py:85} INFO - Job 59: Subtask data_process_service_container
[2023-08-30T13:29:16.341+0100] {task_command.py:415} INFO - Running <TaskInstance: schedule_news_extraction.data_process_service_container manual__2023-08-30T12:02:15.528622+00:00 [running]> on host haboubi-VivoBook-15-ASUS-Laptop-X540UB
[2023-08-30T13:29:16.389+0100] {taskinstance.py:1660} INFO - Exporting env vars: AIRFLOW_CTX_DAG_OWNER='airflow' AIRFLOW_CTX_DAG_ID='schedule_news_extraction' AIRFLOW_CTX_TASK_ID='data_process_service_container' AIRFLOW_CTX_EXECUTION_DATE='2023-08-30T12:02:15.528622+00:00' AIRFLOW_CTX_TRY_NUMBER='5' AIRFLOW_CTX_DAG_RUN_ID='manual__2023-08-30T12:02:15.528622+00:00'
[2023-08-30T13:29:16.421+0100] {docker.py:333} INFO - Starting docker container from image final_dataprocess:latest
[2023-08-30T13:29:16.424+0100] {docker.py:341} WARNING - Using remote engine or docker-in-docker and mounting temporary volume from host is not supported. Falling back to `mount_tmp_dir=False` mode. You can set `mount_tmp_dir` parameter to False to disable mounting and remove the warning
[2023-08-30T13:29:18.715+0100] {docker.py:402} INFO - Welcome to the processing service
[2023-08-30T13:30:08.789+0100] {docker.py:402} INFO - There might be a problem KafkaError{code=UNKNOWN_TOPIC_OR_PART,val=3,str="Subscribed topic not available: None: Broker: Unknown topic or partition"}
There might be a problem KafkaError{code=UNKNOWN_TOPIC_OR_PART,val=3,str="Subscribed topic not available: auto_ingest_news: Broker: Unknown topic or partition"}
[2023-08-30T13:30:45.190+0100] {taskinstance.py:1943} ERROR - Task failed with exception
Traceback (most recent call last):
  File "/home/haboubi/Desktop/final/airflow_folder/py_env/lib/python3.10/site-packages/docker/api/client.py", line 268, in _raise_for_status
    response.raise_for_status()
  File "/home/haboubi/Desktop/final/airflow_folder/py_env/lib/python3.10/site-packages/requests/models.py", line 1021, in raise_for_status
    raise HTTPError(http_error_msg, response=self)
requests.exceptions.HTTPError: 400 Client Error: Bad Request for url: http+docker://localhost/v1.41/containers/create

The above exception was the direct cause of the following exception:

Traceback (most recent call last):
  File "/home/haboubi/Desktop/final/airflow_folder/py_env/lib/python3.10/site-packages/airflow/providers/docker/operators/docker.py", line 338, in _run_image
    return self._run_image_with_mounts(self.mounts + [tmp_mount], add_tmp_variable=True)
  File "/home/haboubi/Desktop/final/airflow_folder/py_env/lib/python3.10/site-packages/airflow/providers/docker/operators/docker.py", line 365, in _run_image_with_mounts
    self.container = self.cli.create_container(
  File "/home/haboubi/Desktop/final/airflow_folder/py_env/lib/python3.10/site-packages/docker/api/container.py", line 431, in create_container
    return self.create_container_from_config(config, name, platform)
  File "/home/haboubi/Desktop/final/airflow_folder/py_env/lib/python3.10/site-packages/docker/api/container.py", line 448, in create_container_from_config
    return self._result(res, True)
  File "/home/haboubi/Desktop/final/airflow_folder/py_env/lib/python3.10/site-packages/docker/api/client.py", line 274, in _result
    self._raise_for_status(response)
  File "/home/haboubi/Desktop/final/airflow_folder/py_env/lib/python3.10/site-packages/docker/api/client.py", line 270, in _raise_for_status
    raise create_api_error_from_http_exception(e) from e
  File "/home/haboubi/Desktop/final/airflow_folder/py_env/lib/python3.10/site-packages/docker/errors.py", line 39, in create_api_error_from_http_exception
    raise cls(e, response=response, explanation=explanation) from e
docker.errors.APIError: 400 Client Error for http+docker://localhost/v1.41/containers/create: Bad Request ("invalid mount config for type "bind": bind source path does not exist: /tmp/airflowtmplfnznz5x")

During handling of the above exception, another exception occurred:

Traceback (most recent call last):
  File "/home/haboubi/Desktop/final/airflow_folder/py_env/lib/python3.10/site-packages/airflow/providers/docker/operators/docker.py", line 476, in execute
    return self._run_image()
  File "/home/haboubi/Desktop/final/airflow_folder/py_env/lib/python3.10/site-packages/airflow/providers/docker/operators/docker.py", line 347, in _run_image
    return self._run_image_with_mounts(self.mounts, add_tmp_variable=False)
  File "/home/haboubi/Desktop/final/airflow_folder/py_env/lib/python3.10/site-packages/airflow/providers/docker/operators/docker.py", line 411, in _run_image_with_mounts
    raise AirflowException(f"Docker container failed: {result!r} lines {joined_log_lines}")
airflow.exceptions.AirflowException: Docker container failed: {'Error': None, 'StatusCode': 137} lines Welcome to the processing service
There might be a problem KafkaError{code=UNKNOWN_TOPIC_OR_PART,val=3,str="Subscribed topic not available: None: Broker: Unknown topic or partition"}
There might be a problem KafkaError{code=UNKNOWN_TOPIC_OR_PART,val=3,str="Subscribed topic not available: auto_ingest_news: Broker: Unknown topic or partition"}
[2023-08-30T13:30:45.196+0100] {taskinstance.py:1400} INFO - Marking task as UP_FOR_RETRY. dag_id=schedule_news_extraction, task_id=data_process_service_container, execution_date=20230830T120215, start_date=20230830T122916, end_date=20230830T123045
[2023-08-30T13:30:45.213+0100] {standard_task_runner.py:104} ERROR - Failed to execute job 59 for task data_process_service_container (Docker container failed: {'Error': None, 'StatusCode': 137} lines Welcome to the processing service
There might be a problem KafkaError{code=UNKNOWN_TOPIC_OR_PART,val=3,str="Subscribed topic not available: None: Broker: Unknown topic or partition"}
There might be a problem KafkaError{code=UNKNOWN_TOPIC_OR_PART,val=3,str="Subscribed topic not available: auto_ingest_news: Broker: Unknown topic or partition"}; 98391)
[2023-08-30T13:30:45.228+0100] {local_task_job_runner.py:228} INFO - Task exited with return code 1
[2023-08-30T13:30:45.248+0100] {taskinstance.py:2784} INFO - 0 downstream tasks scheduled from follow-on schedule check
