[2023-08-30T13:20:45.536+0100] {taskinstance.py:1159} INFO - Dependencies all met for dep_context=non-requeueable deps ti=<TaskInstance: schedule_news_extraction.data_storage_service_container scheduled__2023-08-29T12:00:22.439887+00:00 [queued]>
[2023-08-30T13:20:45.546+0100] {taskinstance.py:1159} INFO - Dependencies all met for dep_context=requeueable deps ti=<TaskInstance: schedule_news_extraction.data_storage_service_container scheduled__2023-08-29T12:00:22.439887+00:00 [queued]>
[2023-08-30T13:20:45.546+0100] {taskinstance.py:1361} INFO - Starting attempt 6 of 6
[2023-08-30T13:20:45.560+0100] {taskinstance.py:1382} INFO - Executing <Task(DockerOperator): data_storage_service_container> on 2023-08-29 12:00:22.439887+00:00
[2023-08-30T13:20:45.565+0100] {standard_task_runner.py:57} INFO - Started process 94103 to run task
[2023-08-30T13:20:45.568+0100] {standard_task_runner.py:84} INFO - Running: ['airflow', 'tasks', 'run', 'schedule_news_extraction', 'data_storage_service_container', 'scheduled__2023-08-29T12:00:22.439887+00:00', '--job-id', '54', '--raw', '--subdir', '/home/haboubi/Desktop/final/airflow_folder/dags/news_schedule.py', '--cfg-path', '/tmp/tmp73w7spe1']
[2023-08-30T13:20:45.568+0100] {standard_task_runner.py:85} INFO - Job 54: Subtask data_storage_service_container
[2023-08-30T13:20:45.613+0100] {task_command.py:415} INFO - Running <TaskInstance: schedule_news_extraction.data_storage_service_container scheduled__2023-08-29T12:00:22.439887+00:00 [running]> on host haboubi-VivoBook-15-ASUS-Laptop-X540UB
[2023-08-30T13:20:45.673+0100] {taskinstance.py:1660} INFO - Exporting env vars: AIRFLOW_CTX_DAG_OWNER='airflow' AIRFLOW_CTX_DAG_ID='schedule_news_extraction' AIRFLOW_CTX_TASK_ID='data_storage_service_container' AIRFLOW_CTX_EXECUTION_DATE='2023-08-29T12:00:22.439887+00:00' AIRFLOW_CTX_TRY_NUMBER='6' AIRFLOW_CTX_DAG_RUN_ID='scheduled__2023-08-29T12:00:22.439887+00:00'
[2023-08-30T13:20:45.712+0100] {docker.py:333} INFO - Starting docker container from image final_datastorage:latest
[2023-08-30T13:20:45.715+0100] {docker.py:341} WARNING - Using remote engine or docker-in-docker and mounting temporary volume from host is not supported. Falling back to `mount_tmp_dir=False` mode. You can set `mount_tmp_dir` parameter to False to disable mounting and remove the warning
[2023-08-30T13:21:13.217+0100] {docker.py:402} INFO - Consumer is successfully initiated
[2023-08-30T13:21:13.218+0100] {docker.py:402} INFO - 
[2023-08-30T13:21:13.267+0100] {docker.py:402} INFO - Traceback (most recent call last):
  File "/usr/local/lib/python3.8/site-packages/sqlalchemy/engine/base.py", line 145, in __init__
[2023-08-30T13:21:13.267+0100] {docker.py:402} INFO - self._dbapi_connection = engine.raw_connection()
  File "/usr/local/lib/python3.8/site-packages/sqlalchemy/engine/base.py", line 3288, in raw_connection
[2023-08-30T13:21:13.268+0100] {docker.py:402} INFO - return self.pool.connect()
  File "/usr/local/lib/python3.8/site-packages/sqlalchemy/pool/base.py", line 452, in connect
[2023-08-30T13:21:13.269+0100] {docker.py:402} INFO - return _ConnectionFairy._checkout(self)
  File "/usr/local/lib/python3.8/site-packages/sqlalchemy/pool/base.py", line 1267, in _checkout
[2023-08-30T13:21:13.269+0100] {docker.py:402} INFO - fairy = _ConnectionRecord.checkout(pool)
  File "/usr/local/lib/python3.8/site-packages/sqlalchemy/pool/base.py", line 716, in checkout
[2023-08-30T13:21:13.270+0100] {docker.py:402} INFO - rec = pool._do_get()
  File "/usr/local/lib/python3.8/site-packages/sqlalchemy/pool/impl.py", line 170, in _do_get
[2023-08-30T13:21:13.271+0100] {docker.py:402} INFO - 
[2023-08-30T13:21:13.272+0100] {docker.py:402} INFO - self._dec_overflow()
[2023-08-30T13:21:13.273+0100] {docker.py:402} INFO - 
[2023-08-30T13:21:13.273+0100] {docker.py:402} INFO - File "/usr/local/lib/python3.8/site-packages/sqlalchemy/util/langhelpers.py", line 147, in __exit__
[2023-08-30T13:21:13.275+0100] {docker.py:402} INFO - raise exc_value.with_traceback(exc_tb)
  File "/usr/local/lib/python3.8/site-packages/sqlalchemy/pool/impl.py", line 167, in _do_get
[2023-08-30T13:21:13.276+0100] {docker.py:402} INFO - 
[2023-08-30T13:21:13.276+0100] {docker.py:402} INFO - return self._create_connection()
[2023-08-30T13:21:13.277+0100] {docker.py:402} INFO - 
[2023-08-30T13:21:13.277+0100] {docker.py:402} INFO - File "/usr/local/lib/python3.8/site-packages/sqlalchemy/pool/base.py", line 393, in _create_connection
[2023-08-30T13:21:13.277+0100] {docker.py:402} INFO - return _ConnectionRecord(self)
[2023-08-30T13:21:13.278+0100] {docker.py:402} INFO - 
[2023-08-30T13:21:13.278+0100] {docker.py:402} INFO - File "/usr/local/lib/python3.8/site-packages/sqlalchemy/pool/base.py", line 678, in __init__
[2023-08-30T13:21:13.279+0100] {docker.py:402} INFO - self.__connect()
[2023-08-30T13:21:13.279+0100] {docker.py:402} INFO - 
[2023-08-30T13:21:13.279+0100] {docker.py:402} INFO - File "/usr/local/lib/python3.8/site-packages/sqlalchemy/pool/base.py", line 903, in __connect
[2023-08-30T13:21:13.280+0100] {docker.py:402} INFO - pool.logger.debug("Error on connect(): %s", e)
[2023-08-30T13:21:13.280+0100] {docker.py:402} INFO - 
[2023-08-30T13:21:13.280+0100] {docker.py:402} INFO - File "/usr/local/lib/python3.8/site-packages/sqlalchemy/util/langhelpers.py", line 147, in __exit__
[2023-08-30T13:21:13.281+0100] {docker.py:402} INFO - raise exc_value.with_traceback(exc_tb)
[2023-08-30T13:21:13.281+0100] {docker.py:402} INFO - 
[2023-08-30T13:21:13.281+0100] {docker.py:402} INFO - File "/usr/local/lib/python3.8/site-packages/sqlalchemy/pool/base.py", line 898, in __connect
[2023-08-30T13:21:13.282+0100] {docker.py:402} INFO - self.dbapi_connection = connection = pool._invoke_creator(self)
  File "/usr/local/lib/python3.8/site-packages/sqlalchemy/engine/create.py", line 637, in connect
[2023-08-30T13:21:13.282+0100] {docker.py:402} INFO - return dialect.connect(*cargs, **cparams)
  File "/usr/local/lib/python3.8/site-packages/sqlalchemy/engine/default.py", line 615, in connect
[2023-08-30T13:21:13.282+0100] {docker.py:402} INFO - return self.loaded_dbapi.connect(*cargs, **cparams)
  File "/usr/local/lib/python3.8/site-packages/psycopg2/__init__.py", line 122, in connect
[2023-08-30T13:21:13.282+0100] {docker.py:402} INFO - conn = _connect(dsn, connection_factory=connection_factory, **kwasync)
psycopg2.OperationalError: could not translate host name "postgres" to address: Temporary failure in name resolution


The above exception was the direct cause of the following exception:

Traceback (most recent call last):
  File "auto_news_script.py", line 35, in <module>
[2023-08-30T13:21:13.282+0100] {docker.py:402} INFO - get_tickets_news=produce_database_diagnostic(producer,topic_dig)
  File "auto_news_script.py", line 21, in produce_database_diagnostic
[2023-08-30T13:21:13.282+0100] {docker.py:402} INFO - all_ticket=get_all_ticket_list(type='news')
  File "/app/entites_APi/Service.py", line 53, in get_all_ticket_list
[2023-08-30T13:21:13.283+0100] {docker.py:402} INFO - tickets=session.query(News_tickets).all()
  File "/usr/local/lib/python3.8/site-packages/sqlalchemy/orm/query.py", line 2688, in all
[2023-08-30T13:21:13.283+0100] {docker.py:402} INFO - return self._iter().all()  # type: ignore
  File "/usr/local/lib/python3.8/site-packages/sqlalchemy/orm/query.py", line 2842, in _iter
[2023-08-30T13:21:13.283+0100] {docker.py:402} INFO - result: Union[ScalarResult[_T], Result[_T]] = self.session.execute(
  File "/usr/local/lib/python3.8/site-packages/sqlalchemy/orm/session.py", line 2262, in execute
[2023-08-30T13:21:13.285+0100] {docker.py:402} INFO - return self._execute_internal(
  File "/usr/local/lib/python3.8/site-packages/sqlalchemy/orm/session.py", line 2134, in _execute_internal
[2023-08-30T13:21:13.285+0100] {docker.py:402} INFO - conn = self._connection_for_bind(bind)
  File "/usr/local/lib/python3.8/site-packages/sqlalchemy/orm/session.py", line 2001, in _connection_for_bind
[2023-08-30T13:21:13.286+0100] {docker.py:402} INFO - return trans._connection_for_bind(engine, execution_options)
  File "<string>", line 2, in _connection_for_bind
[2023-08-30T13:21:13.287+0100] {docker.py:402} INFO - File "/usr/local/lib/python3.8/site-packages/sqlalchemy/orm/state_changes.py", line 139, in _go
[2023-08-30T13:21:13.287+0100] {docker.py:402} INFO - ret_value = fn(self, *arg, **kw)
  File "/usr/local/lib/python3.8/site-packages/sqlalchemy/orm/session.py", line 1126, in _connection_for_bind
[2023-08-30T13:21:13.287+0100] {docker.py:402} INFO - conn = bind.connect()
  File "/usr/local/lib/python3.8/site-packages/sqlalchemy/engine/base.py", line 3264, in connect
[2023-08-30T13:21:13.292+0100] {docker.py:402} INFO - return self._connection_cls(self)
[2023-08-30T13:21:13.293+0100] {docker.py:402} INFO - 
[2023-08-30T13:21:13.293+0100] {docker.py:402} INFO - File "/usr/local/lib/python3.8/site-packages/sqlalchemy/engine/base.py", line 147, in __init__
[2023-08-30T13:21:13.293+0100] {docker.py:402} INFO - Connection._handle_dbapi_exception_noconnection(
[2023-08-30T13:21:13.293+0100] {docker.py:402} INFO - 
[2023-08-30T13:21:13.293+0100] {docker.py:402} INFO - File "/usr/local/lib/python3.8/site-packages/sqlalchemy/engine/base.py", line 2426, in _handle_dbapi_exception_noconnection
[2023-08-30T13:21:13.294+0100] {docker.py:402} INFO - raise sqlalchemy_exception.with_traceback(exc_info[2]) from e
[2023-08-30T13:21:13.294+0100] {docker.py:402} INFO - 
[2023-08-30T13:21:13.294+0100] {docker.py:402} INFO - File "/usr/local/lib/python3.8/site-packages/sqlalchemy/engine/base.py", line 145, in __init__
[2023-08-30T13:21:13.294+0100] {docker.py:402} INFO - 
[2023-08-30T13:21:13.294+0100] {docker.py:402} INFO - self._dbapi_connection = engine.raw_connection()
  File "/usr/local/lib/python3.8/site-packages/sqlalchemy/engine/base.py", line 3288, in raw_connection
[2023-08-30T13:21:13.294+0100] {docker.py:402} INFO - return self.pool.connect()
  File "/usr/local/lib/python3.8/site-packages/sqlalchemy/pool/base.py", line 452, in connect
[2023-08-30T13:21:13.295+0100] {docker.py:402} INFO - return _ConnectionFairy._checkout(self)
  File "/usr/local/lib/python3.8/site-packages/sqlalchemy/pool/base.py", line 1267, in _checkout
[2023-08-30T13:21:13.295+0100] {docker.py:402} INFO - fairy = _ConnectionRecord.checkout(pool)
  File "/usr/local/lib/python3.8/site-packages/sqlalchemy/pool/base.py", line 716, in checkout
[2023-08-30T13:21:13.295+0100] {docker.py:402} INFO - rec = pool._do_get()
  File "/usr/local/lib/python3.8/site-packages/sqlalchemy/pool/impl.py", line 170, in _do_get
[2023-08-30T13:21:13.295+0100] {docker.py:402} INFO - self._dec_overflow()
  File "/usr/local/lib/python3.8/site-packages/sqlalchemy/util/langhelpers.py", line 147, in __exit__
[2023-08-30T13:21:13.295+0100] {docker.py:402} INFO - raise exc_value.with_traceback(exc_tb)
  File "/usr/local/lib/python3.8/site-packages/sqlalchemy/pool/impl.py", line 167, in _do_get
[2023-08-30T13:21:13.296+0100] {docker.py:402} INFO - return self._create_connection()
  File "/usr/local/lib/python3.8/site-packages/sqlalchemy/pool/base.py", line 393, in _create_connection
[2023-08-30T13:21:13.296+0100] {docker.py:402} INFO - return _ConnectionRecord(self)
  File "/usr/local/lib/python3.8/site-packages/sqlalchemy/pool/base.py", line 678, in __init__
[2023-08-30T13:21:13.296+0100] {docker.py:402} INFO - self.__connect()
  File "/usr/local/lib/python3.8/site-packages/sqlalchemy/pool/base.py", line 903, in __connect
[2023-08-30T13:21:13.296+0100] {docker.py:402} INFO - pool.logger.debug("Error on connect(): %s", e)
  File "/usr/local/lib/python3.8/site-packages/sqlalchemy/util/langhelpers.py", line 147, in __exit__
[2023-08-30T13:21:13.297+0100] {docker.py:402} INFO - raise exc_value.with_traceback(exc_tb)
  File "/usr/local/lib/python3.8/site-packages/sqlalchemy/pool/base.py", line 898, in __connect
[2023-08-30T13:21:13.297+0100] {docker.py:402} INFO - 
[2023-08-30T13:21:13.297+0100] {docker.py:402} INFO - self.dbapi_connection = connection = pool._invoke_creator(self)
  File "/usr/local/lib/python3.8/site-packages/sqlalchemy/engine/create.py", line 637, in connect
[2023-08-30T13:21:13.298+0100] {docker.py:402} INFO - return dialect.connect(*cargs, **cparams)
  File "/usr/local/lib/python3.8/site-packages/sqlalchemy/engine/default.py", line 615, in connect
[2023-08-30T13:21:13.298+0100] {docker.py:402} INFO - return self.loaded_dbapi.connect(*cargs, **cparams)
  File "/usr/local/lib/python3.8/site-packages/psycopg2/__init__.py", line 122, in connect
[2023-08-30T13:21:13.298+0100] {docker.py:402} INFO - conn = _connect(dsn, connection_factory=connection_factory, **kwasync)
sqlalchemy.exc.OperationalError
[2023-08-30T13:21:13.298+0100] {docker.py:402} INFO - : (psycopg2.OperationalError) could not translate host name "postgres" to address: Temporary failure in name resolution

(Background on this error at: https://sqlalche.me/e/20/e3q8)
[2023-08-30T13:21:13.708+0100] {taskinstance.py:1943} ERROR - Task failed with exception
Traceback (most recent call last):
  File "/home/haboubi/Desktop/final/airflow_folder/py_env/lib/python3.10/site-packages/docker/api/client.py", line 268, in _raise_for_status
    response.raise_for_status()
  File "/home/haboubi/Desktop/final/airflow_folder/py_env/lib/python3.10/site-packages/requests/models.py", line 1021, in raise_for_status
    raise HTTPError(http_error_msg, response=self)
requests.exceptions.HTTPError: 400 Client Error: Bad Request for url: http+docker://localhost/v1.41/containers/create

The above exception was the direct cause of the following exception:

Traceback (most recent call last):
  File "/home/haboubi/Desktop/final/airflow_folder/py_env/lib/python3.10/site-packages/airflow/providers/docker/operators/docker.py", line 338, in _run_image
    return self._run_image_with_mounts(self.mounts + [tmp_mount], add_tmp_variable=True)
  File "/home/haboubi/Desktop/final/airflow_folder/py_env/lib/python3.10/site-packages/airflow/providers/docker/operators/docker.py", line 365, in _run_image_with_mounts
    self.container = self.cli.create_container(
  File "/home/haboubi/Desktop/final/airflow_folder/py_env/lib/python3.10/site-packages/docker/api/container.py", line 431, in create_container
    return self.create_container_from_config(config, name, platform)
  File "/home/haboubi/Desktop/final/airflow_folder/py_env/lib/python3.10/site-packages/docker/api/container.py", line 448, in create_container_from_config
    return self._result(res, True)
  File "/home/haboubi/Desktop/final/airflow_folder/py_env/lib/python3.10/site-packages/docker/api/client.py", line 274, in _result
    self._raise_for_status(response)
  File "/home/haboubi/Desktop/final/airflow_folder/py_env/lib/python3.10/site-packages/docker/api/client.py", line 270, in _raise_for_status
    raise create_api_error_from_http_exception(e) from e
  File "/home/haboubi/Desktop/final/airflow_folder/py_env/lib/python3.10/site-packages/docker/errors.py", line 39, in create_api_error_from_http_exception
    raise cls(e, response=response, explanation=explanation) from e
docker.errors.APIError: 400 Client Error for http+docker://localhost/v1.41/containers/create: Bad Request ("invalid mount config for type "bind": bind source path does not exist: /tmp/airflowtmpb_v59da3")

During handling of the above exception, another exception occurred:

Traceback (most recent call last):
  File "/home/haboubi/Desktop/final/airflow_folder/py_env/lib/python3.10/site-packages/airflow/providers/docker/operators/docker.py", line 476, in execute
    return self._run_image()
  File "/home/haboubi/Desktop/final/airflow_folder/py_env/lib/python3.10/site-packages/airflow/providers/docker/operators/docker.py", line 347, in _run_image
    return self._run_image_with_mounts(self.mounts, add_tmp_variable=False)
  File "/home/haboubi/Desktop/final/airflow_folder/py_env/lib/python3.10/site-packages/airflow/providers/docker/operators/docker.py", line 411, in _run_image_with_mounts
    raise AirflowException(f"Docker container failed: {result!r} lines {joined_log_lines}")
airflow.exceptions.AirflowException: Docker container failed: {'Error': None, 'StatusCode': 1} lines Consumer is successfully initiated

Traceback (most recent call last):
  File "/usr/local/lib/python3.8/site-packages/sqlalchemy/engine/base.py", line 145, in __init__
self._dbapi_connection = engine.raw_connection()
  File "/usr/local/lib/python3.8/site-packages/sqlalchemy/engine/base.py", line 3288, in raw_connection
return self.pool.connect()
  File "/usr/local/lib/python3.8/site-packages/sqlalchemy/pool/base.py", line 452, in connect
return _ConnectionFairy._checkout(self)
  File "/usr/local/lib/python3.8/site-packages/sqlalchemy/pool/base.py", line 1267, in _checkout
fairy = _ConnectionRecord.checkout(pool)
  File "/usr/local/lib/python3.8/site-packages/sqlalchemy/pool/base.py", line 716, in checkout
rec = pool._do_get()
  File "/usr/local/lib/python3.8/site-packages/sqlalchemy/pool/impl.py", line 170, in _do_get

self._dec_overflow()

File "/usr/local/lib/python3.8/site-packages/sqlalchemy/util/langhelpers.py", line 147, in __exit__
raise exc_value.with_traceback(exc_tb)
  File "/usr/local/lib/python3.8/site-packages/sqlalchemy/pool/impl.py", line 167, in _do_get

return self._create_connection()

File "/usr/local/lib/python3.8/site-packages/sqlalchemy/pool/base.py", line 393, in _create_connection
return _ConnectionRecord(self)

File "/usr/local/lib/python3.8/site-packages/sqlalchemy/pool/base.py", line 678, in __init__
self.__connect()

File "/usr/local/lib/python3.8/site-packages/sqlalchemy/pool/base.py", line 903, in __connect
pool.logger.debug("Error on connect(): %s", e)

File "/usr/local/lib/python3.8/site-packages/sqlalchemy/util/langhelpers.py", line 147, in __exit__
raise exc_value.with_traceback(exc_tb)

File "/usr/local/lib/python3.8/site-packages/sqlalchemy/pool/base.py", line 898, in __connect
self.dbapi_connection = connection = pool._invoke_creator(self)
  File "/usr/local/lib/python3.8/site-packages/sqlalchemy/engine/create.py", line 637, in connect
return dialect.connect(*cargs, **cparams)
  File "/usr/local/lib/python3.8/site-packages/sqlalchemy/engine/default.py", line 615, in connect
return self.loaded_dbapi.connect(*cargs, **cparams)
  File "/usr/local/lib/python3.8/site-packages/psycopg2/__init__.py", line 122, in connect
conn = _connect(dsn, connection_factory=connection_factory, **kwasync)
psycopg2.OperationalError: could not translate host name "postgres" to address: Temporary failure in name resolution


The above exception was the direct cause of the following exception:

Traceback (most recent call last):
  File "auto_news_script.py", line 35, in <module>
get_tickets_news=produce_database_diagnostic(producer,topic_dig)
  File "auto_news_script.py", line 21, in produce_database_diagnostic
all_ticket=get_all_ticket_list(type='news')
  File "/app/entites_APi/Service.py", line 53, in get_all_ticket_list
tickets=session.query(News_tickets).all()
  File "/usr/local/lib/python3.8/site-packages/sqlalchemy/orm/query.py", line 2688, in all
return self._iter().all()  # type: ignore
  File "/usr/local/lib/python3.8/site-packages/sqlalchemy/orm/query.py", line 2842, in _iter
result: Union[ScalarResult[_T], Result[_T]] = self.session.execute(
  File "/usr/local/lib/python3.8/site-packages/sqlalchemy/orm/session.py", line 2262, in execute
return self._execute_internal(
  File "/usr/local/lib/python3.8/site-packages/sqlalchemy/orm/session.py", line 2134, in _execute_internal
conn = self._connection_for_bind(bind)
  File "/usr/local/lib/python3.8/site-packages/sqlalchemy/orm/session.py", line 2001, in _connection_for_bind
return trans._connection_for_bind(engine, execution_options)
  File "<string>", line 2, in _connection_for_bind
File "/usr/local/lib/python3.8/site-packages/sqlalchemy/orm/state_changes.py", line 139, in _go
ret_value = fn(self, *arg, **kw)
  File "/usr/local/lib/python3.8/site-packages/sqlalchemy/orm/session.py", line 1126, in _connection_for_bind
conn = bind.connect()
  File "/usr/local/lib/python3.8/site-packages/sqlalchemy/engine/base.py", line 3264, in connect
return self._connection_cls(self)

File "/usr/local/lib/python3.8/site-packages/sqlalchemy/engine/base.py", line 147, in __init__
Connection._handle_dbapi_exception_noconnection(

File "/usr/local/lib/python3.8/site-packages/sqlalchemy/engine/base.py", line 2426, in _handle_dbapi_exception_noconnection
raise sqlalchemy_exception.with_traceback(exc_info[2]) from e

File "/usr/local/lib/python3.8/site-packages/sqlalchemy/engine/base.py", line 145, in __init__

self._dbapi_connection = engine.raw_connection()
  File "/usr/local/lib/python3.8/site-packages/sqlalchemy/engine/base.py", line 3288, in raw_connection
return self.pool.connect()
  File "/usr/local/lib/python3.8/site-packages/sqlalchemy/pool/base.py", line 452, in connect
return _ConnectionFairy._checkout(self)
  File "/usr/local/lib/python3.8/site-packages/sqlalchemy/pool/base.py", line 1267, in _checkout
fairy = _ConnectionRecord.checkout(pool)
  File "/usr/local/lib/python3.8/site-packages/sqlalchemy/pool/base.py", line 716, in checkout
rec = pool._do_get()
  File "/usr/local/lib/python3.8/site-packages/sqlalchemy/pool/impl.py", line 170, in _do_get
self._dec_overflow()
  File "/usr/local/lib/python3.8/site-packages/sqlalchemy/util/langhelpers.py", line 147, in __exit__
raise exc_value.with_traceback(exc_tb)
  File "/usr/local/lib/python3.8/site-packages/sqlalchemy/pool/impl.py", line 167, in _do_get
return self._create_connection()
  File "/usr/local/lib/python3.8/site-packages/sqlalchemy/pool/base.py", line 393, in _create_connection
return _ConnectionRecord(self)
  File "/usr/local/lib/python3.8/site-packages/sqlalchemy/pool/base.py", line 678, in __init__
self.__connect()
  File "/usr/local/lib/python3.8/site-packages/sqlalchemy/pool/base.py", line 903, in __connect
pool.logger.debug("Error on connect(): %s", e)
  File "/usr/local/lib/python3.8/site-packages/sqlalchemy/util/langhelpers.py", line 147, in __exit__
raise exc_value.with_traceback(exc_tb)
  File "/usr/local/lib/python3.8/site-packages/sqlalchemy/pool/base.py", line 898, in __connect

self.dbapi_connection = connection = pool._invoke_creator(self)
  File "/usr/local/lib/python3.8/site-packages/sqlalchemy/engine/create.py", line 637, in connect
return dialect.connect(*cargs, **cparams)
  File "/usr/local/lib/python3.8/site-packages/sqlalchemy/engine/default.py", line 615, in connect
return self.loaded_dbapi.connect(*cargs, **cparams)
  File "/usr/local/lib/python3.8/site-packages/psycopg2/__init__.py", line 122, in connect
conn = _connect(dsn, connection_factory=connection_factory, **kwasync)
sqlalchemy.exc.OperationalError
: (psycopg2.OperationalError) could not translate host name "postgres" to address: Temporary failure in name resolution

(Background on this error at: https://sqlalche.me/e/20/e3q8)
[2023-08-30T13:21:13.711+0100] {taskinstance.py:1400} INFO - Marking task as FAILED. dag_id=schedule_news_extraction, task_id=data_storage_service_container, execution_date=20230829T120022, start_date=20230830T122045, end_date=20230830T122113
[2023-08-30T13:21:13.724+0100] {standard_task_runner.py:104} ERROR - Failed to execute job 54 for task data_storage_service_container (Docker container failed: {'Error': None, 'StatusCode': 1} lines Consumer is successfully initiated

Traceback (most recent call last):
  File "/usr/local/lib/python3.8/site-packages/sqlalchemy/engine/base.py", line 145, in __init__
self._dbapi_connection = engine.raw_connection()
  File "/usr/local/lib/python3.8/site-packages/sqlalchemy/engine/base.py", line 3288, in raw_connection
return self.pool.connect()
  File "/usr/local/lib/python3.8/site-packages/sqlalchemy/pool/base.py", line 452, in connect
return _ConnectionFairy._checkout(self)
  File "/usr/local/lib/python3.8/site-packages/sqlalchemy/pool/base.py", line 1267, in _checkout
fairy = _ConnectionRecord.checkout(pool)
  File "/usr/local/lib/python3.8/site-packages/sqlalchemy/pool/base.py", line 716, in checkout
rec = pool._do_get()
  File "/usr/local/lib/python3.8/site-packages/sqlalchemy/pool/impl.py", line 170, in _do_get

self._dec_overflow()

File "/usr/local/lib/python3.8/site-packages/sqlalchemy/util/langhelpers.py", line 147, in __exit__
raise exc_value.with_traceback(exc_tb)
  File "/usr/local/lib/python3.8/site-packages/sqlalchemy/pool/impl.py", line 167, in _do_get

return self._create_connection()

File "/usr/local/lib/python3.8/site-packages/sqlalchemy/pool/base.py", line 393, in _create_connection
return _ConnectionRecord(self)

File "/usr/local/lib/python3.8/site-packages/sqlalchemy/pool/base.py", line 678, in __init__
self.__connect()

File "/usr/local/lib/python3.8/site-packages/sqlalchemy/pool/base.py", line 903, in __connect
pool.logger.debug("Error on connect(): %s", e)

File "/usr/local/lib/python3.8/site-packages/sqlalchemy/util/langhelpers.py", line 147, in __exit__
raise exc_value.with_traceback(exc_tb)

File "/usr/local/lib/python3.8/site-packages/sqlalchemy/pool/base.py", line 898, in __connect
self.dbapi_connection = connection = pool._invoke_creator(self)
  File "/usr/local/lib/python3.8/site-packages/sqlalchemy/engine/create.py", line 637, in connect
return dialect.connect(*cargs, **cparams)
  File "/usr/local/lib/python3.8/site-packages/sqlalchemy/engine/default.py", line 615, in connect
return self.loaded_dbapi.connect(*cargs, **cparams)
  File "/usr/local/lib/python3.8/site-packages/psycopg2/__init__.py", line 122, in connect
conn = _connect(dsn, connection_factory=connection_factory, **kwasync)
psycopg2.OperationalError: could not translate host name "postgres" to address: Temporary failure in name resolution


The above exception was the direct cause of the following exception:

Traceback (most recent call last):
  File "auto_news_script.py", line 35, in <module>
get_tickets_news=produce_database_diagnostic(producer,topic_dig)
  File "auto_news_script.py", line 21, in produce_database_diagnostic
all_ticket=get_all_ticket_list(type='news')
  File "/app/entites_APi/Service.py", line 53, in get_all_ticket_list
tickets=session.query(News_tickets).all()
  File "/usr/local/lib/python3.8/site-packages/sqlalchemy/orm/query.py", line 2688, in all
return self._iter().all()  # type: ignore
  File "/usr/local/lib/python3.8/site-packages/sqlalchemy/orm/query.py", line 2842, in _iter
result: Union[ScalarResult[_T], Result[_T]] = self.session.execute(
  File "/usr/local/lib/python3.8/site-packages/sqlalchemy/orm/session.py", line 2262, in execute
return self._execute_internal(
  File "/usr/local/lib/python3.8/site-packages/sqlalchemy/orm/session.py", line 2134, in _execute_internal
conn = self._connection_for_bind(bind)
  File "/usr/local/lib/python3.8/site-packages/sqlalchemy/orm/session.py", line 2001, in _connection_for_bind
return trans._connection_for_bind(engine, execution_options)
  File "<string>", line 2, in _connection_for_bind
File "/usr/local/lib/python3.8/site-packages/sqlalchemy/orm/state_changes.py", line 139, in _go
ret_value = fn(self, *arg, **kw)
  File "/usr/local/lib/python3.8/site-packages/sqlalchemy/orm/session.py", line 1126, in _connection_for_bind
conn = bind.connect()
  File "/usr/local/lib/python3.8/site-packages/sqlalchemy/engine/base.py", line 3264, in connect
return self._connection_cls(self)

File "/usr/local/lib/python3.8/site-packages/sqlalchemy/engine/base.py", line 147, in __init__
Connection._handle_dbapi_exception_noconnection(

File "/usr/local/lib/python3.8/site-packages/sqlalchemy/engine/base.py", line 2426, in _handle_dbapi_exception_noconnection
raise sqlalchemy_exception.with_traceback(exc_info[2]) from e

File "/usr/local/lib/python3.8/site-packages/sqlalchemy/engine/base.py", line 145, in __init__

self._dbapi_connection = engine.raw_connection()
  File "/usr/local/lib/python3.8/site-packages/sqlalchemy/engine/base.py", line 3288, in raw_connection
return self.pool.connect()
  File "/usr/local/lib/python3.8/site-packages/sqlalchemy/pool/base.py", line 452, in connect
return _ConnectionFairy._checkout(self)
  File "/usr/local/lib/python3.8/site-packages/sqlalchemy/pool/base.py", line 1267, in _checkout
fairy = _ConnectionRecord.checkout(pool)
  File "/usr/local/lib/python3.8/site-packages/sqlalchemy/pool/base.py", line 716, in checkout
rec = pool._do_get()
  File "/usr/local/lib/python3.8/site-packages/sqlalchemy/pool/impl.py", line 170, in _do_get
self._dec_overflow()
  File "/usr/local/lib/python3.8/site-packages/sqlalchemy/util/langhelpers.py", line 147, in __exit__
raise exc_value.with_traceback(exc_tb)
  File "/usr/local/lib/python3.8/site-packages/sqlalchemy/pool/impl.py", line 167, in _do_get
return self._create_connection()
  File "/usr/local/lib/python3.8/site-packages/sqlalchemy/pool/base.py", line 393, in _create_connection
return _ConnectionRecord(self)
  File "/usr/local/lib/python3.8/site-packages/sqlalchemy/pool/base.py", line 678, in __init__
self.__connect()
  File "/usr/local/lib/python3.8/site-packages/sqlalchemy/pool/base.py", line 903, in __connect
pool.logger.debug("Error on connect(): %s", e)
  File "/usr/local/lib/python3.8/site-packages/sqlalchemy/util/langhelpers.py", line 147, in __exit__
raise exc_value.with_traceback(exc_tb)
  File "/usr/local/lib/python3.8/site-packages/sqlalchemy/pool/base.py", line 898, in __connect

self.dbapi_connection = connection = pool._invoke_creator(self)
  File "/usr/local/lib/python3.8/site-packages/sqlalchemy/engine/create.py", line 637, in connect
return dialect.connect(*cargs, **cparams)
  File "/usr/local/lib/python3.8/site-packages/sqlalchemy/engine/default.py", line 615, in connect
return self.loaded_dbapi.connect(*cargs, **cparams)
  File "/usr/local/lib/python3.8/site-packages/psycopg2/__init__.py", line 122, in connect
conn = _connect(dsn, connection_factory=connection_factory, **kwasync)
sqlalchemy.exc.OperationalError
: (psycopg2.OperationalError) could not translate host name "postgres" to address: Temporary failure in name resolution

(Background on this error at: https://sqlalche.me/e/20/e3q8); 94103)
[2023-08-30T13:21:13.749+0100] {local_task_job_runner.py:228} INFO - Task exited with return code 1
[2023-08-30T13:21:13.766+0100] {taskinstance.py:2784} INFO - 0 downstream tasks scheduled from follow-on schedule check
