[2023-08-30T13:06:34.961+0100] {taskinstance.py:1159} INFO - Dependencies all met for dep_context=non-requeueable deps ti=<TaskInstance: schedule_news_extraction.data_storage_service_container manual__2023-08-30T12:02:15.528622+00:00 [queued]>
[2023-08-30T13:06:34.967+0100] {taskinstance.py:1159} INFO - Dependencies all met for dep_context=requeueable deps ti=<TaskInstance: schedule_news_extraction.data_storage_service_container manual__2023-08-30T12:02:15.528622+00:00 [queued]>
[2023-08-30T13:06:34.967+0100] {taskinstance.py:1361} INFO - Starting attempt 3 of 6
[2023-08-30T13:06:34.980+0100] {taskinstance.py:1382} INFO - Executing <Task(DockerOperator): data_storage_service_container> on 2023-08-30 12:02:15.528622+00:00
[2023-08-30T13:06:34.983+0100] {standard_task_runner.py:57} INFO - Started process 87763 to run task
[2023-08-30T13:06:34.986+0100] {standard_task_runner.py:84} INFO - Running: ['airflow', 'tasks', 'run', 'schedule_news_extraction', 'data_storage_service_container', 'manual__2023-08-30T12:02:15.528622+00:00', '--job-id', '32', '--raw', '--subdir', '/home/haboubi/Desktop/final/airflow_folder/dags/news_schedule.py', '--cfg-path', '/tmp/tmp0oqb_ots']
[2023-08-30T13:06:34.987+0100] {standard_task_runner.py:85} INFO - Job 32: Subtask data_storage_service_container
[2023-08-30T13:06:35.017+0100] {task_command.py:415} INFO - Running <TaskInstance: schedule_news_extraction.data_storage_service_container manual__2023-08-30T12:02:15.528622+00:00 [running]> on host haboubi-VivoBook-15-ASUS-Laptop-X540UB
[2023-08-30T13:06:35.062+0100] {taskinstance.py:1660} INFO - Exporting env vars: AIRFLOW_CTX_DAG_OWNER='airflow' AIRFLOW_CTX_DAG_ID='schedule_news_extraction' AIRFLOW_CTX_TASK_ID='data_storage_service_container' AIRFLOW_CTX_EXECUTION_DATE='2023-08-30T12:02:15.528622+00:00' AIRFLOW_CTX_TRY_NUMBER='3' AIRFLOW_CTX_DAG_RUN_ID='manual__2023-08-30T12:02:15.528622+00:00'
[2023-08-30T13:06:35.066+0100] {taskinstance.py:1943} ERROR - Task failed with exception
Traceback (most recent call last):
  File "/home/haboubi/Desktop/final/airflow_folder/py_env/lib/python3.10/site-packages/urllib3/connectionpool.py", line 714, in urlopen
    httplib_response = self._make_request(
  File "/home/haboubi/Desktop/final/airflow_folder/py_env/lib/python3.10/site-packages/urllib3/connectionpool.py", line 415, in _make_request
    conn.request(method, url, **httplib_request_kw)
  File "/home/haboubi/Desktop/final/airflow_folder/py_env/lib/python3.10/site-packages/urllib3/connection.py", line 244, in request
    super(HTTPConnection, self).request(method, url, body=body, headers=headers)
  File "/usr/lib/python3.10/http/client.py", line 1283, in request
    self._send_request(method, url, body, headers, encode_chunked)
  File "/usr/lib/python3.10/http/client.py", line 1329, in _send_request
    self.endheaders(body, encode_chunked=encode_chunked)
  File "/usr/lib/python3.10/http/client.py", line 1278, in endheaders
    self._send_output(message_body, encode_chunked=encode_chunked)
  File "/usr/lib/python3.10/http/client.py", line 1038, in _send_output
    self.send(msg)
  File "/usr/lib/python3.10/http/client.py", line 976, in send
    self.connect()
  File "/home/haboubi/Desktop/final/airflow_folder/py_env/lib/python3.10/site-packages/docker/transport/unixconn.py", line 27, in connect
    sock.connect(self.unix_socket)
PermissionError: [Errno 13] Permission denied

During handling of the above exception, another exception occurred:

Traceback (most recent call last):
  File "/home/haboubi/Desktop/final/airflow_folder/py_env/lib/python3.10/site-packages/requests/adapters.py", line 486, in send
    resp = conn.urlopen(
  File "/home/haboubi/Desktop/final/airflow_folder/py_env/lib/python3.10/site-packages/urllib3/connectionpool.py", line 798, in urlopen
    retries = retries.increment(
  File "/home/haboubi/Desktop/final/airflow_folder/py_env/lib/python3.10/site-packages/urllib3/util/retry.py", line 550, in increment
    raise six.reraise(type(error), error, _stacktrace)
  File "/home/haboubi/Desktop/final/airflow_folder/py_env/lib/python3.10/site-packages/urllib3/packages/six.py", line 769, in reraise
    raise value.with_traceback(tb)
  File "/home/haboubi/Desktop/final/airflow_folder/py_env/lib/python3.10/site-packages/urllib3/connectionpool.py", line 714, in urlopen
    httplib_response = self._make_request(
  File "/home/haboubi/Desktop/final/airflow_folder/py_env/lib/python3.10/site-packages/urllib3/connectionpool.py", line 415, in _make_request
    conn.request(method, url, **httplib_request_kw)
  File "/home/haboubi/Desktop/final/airflow_folder/py_env/lib/python3.10/site-packages/urllib3/connection.py", line 244, in request
    super(HTTPConnection, self).request(method, url, body=body, headers=headers)
  File "/usr/lib/python3.10/http/client.py", line 1283, in request
    self._send_request(method, url, body, headers, encode_chunked)
  File "/usr/lib/python3.10/http/client.py", line 1329, in _send_request
    self.endheaders(body, encode_chunked=encode_chunked)
  File "/usr/lib/python3.10/http/client.py", line 1278, in endheaders
    self._send_output(message_body, encode_chunked=encode_chunked)
  File "/usr/lib/python3.10/http/client.py", line 1038, in _send_output
    self.send(msg)
  File "/usr/lib/python3.10/http/client.py", line 976, in send
    self.connect()
  File "/home/haboubi/Desktop/final/airflow_folder/py_env/lib/python3.10/site-packages/docker/transport/unixconn.py", line 27, in connect
    sock.connect(self.unix_socket)
urllib3.exceptions.ProtocolError: ('Connection aborted.', PermissionError(13, 'Permission denied'))

During handling of the above exception, another exception occurred:

Traceback (most recent call last):
  File "/home/haboubi/Desktop/final/airflow_folder/py_env/lib/python3.10/site-packages/docker/api/client.py", line 214, in _retrieve_server_version
    return self.version(api_version=False)["ApiVersion"]
  File "/home/haboubi/Desktop/final/airflow_folder/py_env/lib/python3.10/site-packages/docker/api/daemon.py", line 181, in version
    return self._result(self._get(url), json=True)
  File "/home/haboubi/Desktop/final/airflow_folder/py_env/lib/python3.10/site-packages/docker/utils/decorators.py", line 46, in inner
    return f(self, *args, **kwargs)
  File "/home/haboubi/Desktop/final/airflow_folder/py_env/lib/python3.10/site-packages/docker/api/client.py", line 237, in _get
    return self.get(url, **self._set_request_timeout(kwargs))
  File "/home/haboubi/Desktop/final/airflow_folder/py_env/lib/python3.10/site-packages/requests/sessions.py", line 602, in get
    return self.request("GET", url, **kwargs)
  File "/home/haboubi/Desktop/final/airflow_folder/py_env/lib/python3.10/site-packages/requests/sessions.py", line 589, in request
    resp = self.send(prep, **send_kwargs)
  File "/home/haboubi/Desktop/final/airflow_folder/py_env/lib/python3.10/site-packages/requests/sessions.py", line 703, in send
    r = adapter.send(request, **kwargs)
  File "/home/haboubi/Desktop/final/airflow_folder/py_env/lib/python3.10/site-packages/requests/adapters.py", line 501, in send
    raise ConnectionError(err, request=request)
requests.exceptions.ConnectionError: ('Connection aborted.', PermissionError(13, 'Permission denied'))

During handling of the above exception, another exception occurred:

Traceback (most recent call last):
  File "/home/haboubi/Desktop/final/airflow_folder/py_env/lib/python3.10/site-packages/airflow/providers/docker/operators/docker.py", line 459, in execute
    if self.force_pull or not self.cli.images(name=self.image):
  File "/home/haboubi/Desktop/final/airflow_folder/py_env/lib/python3.10/site-packages/airflow/providers/docker/operators/docker.py", line 329, in cli
    return self.hook.api_client
  File "/usr/lib/python3.10/functools.py", line 981, in __get__
    val = self.func(instance)
  File "/home/haboubi/Desktop/final/airflow_folder/py_env/lib/python3.10/site-packages/airflow/providers/docker/hooks/docker.py", line 120, in api_client
    client = APIClient(
  File "/home/haboubi/Desktop/final/airflow_folder/py_env/lib/python3.10/site-packages/docker/api/client.py", line 197, in __init__
    self._version = self._retrieve_server_version()
  File "/home/haboubi/Desktop/final/airflow_folder/py_env/lib/python3.10/site-packages/docker/api/client.py", line 221, in _retrieve_server_version
    raise DockerException(
docker.errors.DockerException: Error while fetching server API version: ('Connection aborted.', PermissionError(13, 'Permission denied'))
[2023-08-30T13:06:35.071+0100] {taskinstance.py:1400} INFO - Marking task as UP_FOR_RETRY. dag_id=schedule_news_extraction, task_id=data_storage_service_container, execution_date=20230830T120215, start_date=20230830T120634, end_date=20230830T120635
[2023-08-30T13:06:35.081+0100] {standard_task_runner.py:104} ERROR - Failed to execute job 32 for task data_storage_service_container (Error while fetching server API version: ('Connection aborted.', PermissionError(13, 'Permission denied')); 87763)
[2023-08-30T13:06:35.118+0100] {local_task_job_runner.py:228} INFO - Task exited with return code 1
[2023-08-30T13:06:35.138+0100] {taskinstance.py:2784} INFO - 0 downstream tasks scheduled from follow-on schedule check
